[2018-06-06 14:03:06,789] ERROR in app: Exception on /exp [GET]
Traceback (most recent call last):
  File "/usr/local/lib/python2.7/site-packages/flask/app.py", line 1982, in wsgi_app
    response = self.full_dispatch_request()
  File "/usr/local/lib/python2.7/site-packages/flask/app.py", line 1614, in full_dispatch_request
    rv = self.handle_user_exception(e)
  File "/usr/local/lib/python2.7/site-packages/flask/app.py", line 1517, in handle_user_exception
    reraise(exc_type, exc_value, tb)
  File "/usr/local/lib/python2.7/site-packages/flask/app.py", line 1612, in full_dispatch_request
    rv = self.dispatch_request()
  File "/usr/local/lib/python2.7/site-packages/flask/app.py", line 1598, in dispatch_request
    return self.view_functions[rule.endpoint](**req.view_args)
  File "/usr/local/lib/python2.7/site-packages/psiturk/user_utils.py", line 20, in new_func
    resp = make_response(func(*args, **kwargs))
  File "/usr/local/lib/python2.7/site-packages/psiturk/experiment.py", line 439, in start_exp
    db_session.commit()
  File "/usr/local/lib/python2.7/site-packages/sqlalchemy/orm/scoping.py", line 149, in do
    return getattr(self.registry(), name)(*args, **kwargs)
  File "/usr/local/lib/python2.7/site-packages/sqlalchemy/orm/session.py", line 721, in commit
    self.transaction.commit()
  File "/usr/local/lib/python2.7/site-packages/sqlalchemy/orm/session.py", line 354, in commit
    self._prepare_impl()
  File "/usr/local/lib/python2.7/site-packages/sqlalchemy/orm/session.py", line 334, in _prepare_impl
    self.session.flush()
  File "/usr/local/lib/python2.7/site-packages/sqlalchemy/orm/session.py", line 1818, in flush
    self._flush(objects)
  File "/usr/local/lib/python2.7/site-packages/sqlalchemy/orm/session.py", line 1936, in _flush
    transaction.rollback(_capture_exception=True)
  File "/usr/local/lib/python2.7/site-packages/sqlalchemy/util/langhelpers.py", line 58, in __exit__
    compat.reraise(exc_type, exc_value, exc_tb)
  File "/usr/local/lib/python2.7/site-packages/sqlalchemy/orm/session.py", line 1900, in _flush
    flush_context.execute()
  File "/usr/local/lib/python2.7/site-packages/sqlalchemy/orm/unitofwork.py", line 372, in execute
    rec.execute(self)
  File "/usr/local/lib/python2.7/site-packages/sqlalchemy/orm/unitofwork.py", line 525, in execute
    uow
  File "/usr/local/lib/python2.7/site-packages/sqlalchemy/orm/persistence.py", line 64, in save_obj
    table, insert)
  File "/usr/local/lib/python2.7/site-packages/sqlalchemy/orm/persistence.py", line 541, in _emit_insert_statements
    execute(statement, multiparams)
  File "/usr/local/lib/python2.7/site-packages/sqlalchemy/engine/base.py", line 662, in execute
    params)
  File "/usr/local/lib/python2.7/site-packages/sqlalchemy/engine/base.py", line 761, in _execute_clauseelement
    compiled_sql, distilled_params
  File "/usr/local/lib/python2.7/site-packages/sqlalchemy/engine/base.py", line 874, in _execute_context
    context)
  File "/usr/local/lib/python2.7/site-packages/sqlalchemy/engine/base.py", line 1024, in _handle_dbapi_exception
    exc_info
  File "/usr/local/lib/python2.7/site-packages/sqlalchemy/util/compat.py", line 196, in raise_from_cause
    reraise(type(exception), exception, tb=exc_tb)
  File "/usr/local/lib/python2.7/site-packages/sqlalchemy/engine/base.py", line 867, in _execute_context
    context)
  File "/usr/local/lib/python2.7/site-packages/sqlalchemy/engine/default.py", line 324, in do_execute
    cursor.execute(statement, parameters)
IntegrityError: (IntegrityError) duplicate key value violates unique constraint "artTask_pkey"
DETAIL:  Key (uniqueid)=(debugpx1JH:debugfcOyH) already exists.
 'INSERT INTO "artTask" (uniqueid, assignmentid, workerid, hitid, ipaddress, browser, platform, language, cond, counterbalance, codeversion, beginhit, beginexp, endhit, bonus, status, mode, datastring) VALUES (%(uniqueid)s, %(assignmentid)s, %(workerid)s, %(hitid)s, %(ipaddress)s, %(browser)s, %(platform)s, %(language)s, %(cond)s, %(counterbalance)s, %(codeversion)s, %(beginhit)s, %(beginexp)s, %(endhit)s, %(bonus)s, %(status)s, %(mode)s, %(datastring)s)' {'beginexp': None, 'status': 1, 'language': 'UNKNOWN', 'beginhit': datetime.datetime(2018, 6, 6, 14, 3, 6, 635025), 'platform': 'macos', 'bonus': 0, 'workerid': u'debugpx1JH', 'endhit': None, 'mode': u'debug', 'datastring': None, 'cond': 0, 'hitid': u'debugQpTJJ', 'uniqueid': 'debugpx1JH:debugfcOyH', 'counterbalance': 0, 'assignmentid': u'debugfcOyH', 'ipaddress': '127.0.0.1', 'codeversion': '1.0', 'browser': 'chrome'}
[2018-06-06 15:28:39 -0700] [50067] [CRITICAL] WORKER TIMEOUT (pid:50081)
[2018-06-06 15:28:39 -0700] [50067] [CRITICAL] WORKER TIMEOUT (pid:50082)
[2018-06-06 15:28:39 -0700] [50067] [CRITICAL] WORKER TIMEOUT (pid:50083)
[2018-06-06 15:28:39 -0700] [50067] [CRITICAL] WORKER TIMEOUT (pid:50084)
[2018-06-06 15:28:39 -0700] [50067] [CRITICAL] WORKER TIMEOUT (pid:50085)
[2018-06-06 15:28:39 -0700] [50067] [CRITICAL] WORKER TIMEOUT (pid:50086)
[2018-06-06 15:28:39 -0700] [50067] [CRITICAL] WORKER TIMEOUT (pid:50087)
[2018-06-06 15:28:39 -0700] [50067] [CRITICAL] WORKER TIMEOUT (pid:50089)
[2018-06-06 15:28:39 -0700] [50067] [CRITICAL] WORKER TIMEOUT (pid:50090)
[2018-06-06 15:28:39 -0700] [50067] [CRITICAL] WORKER TIMEOUT (pid:50091)
[2018-06-06 15:28:39 -0700] [50067] [CRITICAL] WORKER TIMEOUT (pid:50092)
[2018-06-06 15:28:39 -0700] [50067] [CRITICAL] WORKER TIMEOUT (pid:50093)
[2018-06-06 15:28:39 -0700] [50067] [CRITICAL] WORKER TIMEOUT (pid:50072)
[2018-06-06 15:28:39 -0700] [50067] [CRITICAL] WORKER TIMEOUT (pid:50076)
[2018-06-06 15:28:39 -0700] [50067] [CRITICAL] WORKER TIMEOUT (pid:50077)
[2018-06-06 15:28:39 -0700] [50067] [CRITICAL] WORKER TIMEOUT (pid:50078)
[2018-06-06 15:30:40 -0700] [50067] [CRITICAL] WORKER TIMEOUT (pid:50088)
[2018-06-06 15:30:43 -0700] [50067] [CRITICAL] WORKER TIMEOUT (pid:66792)
[2018-06-06 15:30:43 -0700] [50067] [CRITICAL] WORKER TIMEOUT (pid:66793)
[2018-06-06 15:30:43 -0700] [50067] [CRITICAL] WORKER TIMEOUT (pid:66794)
[2018-06-06 15:30:43 -0700] [50067] [CRITICAL] WORKER TIMEOUT (pid:66795)
[2018-06-06 15:30:43 -0700] [50067] [CRITICAL] WORKER TIMEOUT (pid:66796)
[2018-06-06 15:30:43 -0700] [50067] [CRITICAL] WORKER TIMEOUT (pid:66799)
[2018-06-06 15:30:43 -0700] [50067] [CRITICAL] WORKER TIMEOUT (pid:66800)
[2018-06-06 15:30:43 -0700] [50067] [CRITICAL] WORKER TIMEOUT (pid:66801)
[2018-06-06 15:30:43 -0700] [50067] [CRITICAL] WORKER TIMEOUT (pid:66803)
[2018-06-06 15:30:43 -0700] [50067] [CRITICAL] WORKER TIMEOUT (pid:66804)
[2018-06-06 15:30:43 -0700] [50067] [CRITICAL] WORKER TIMEOUT (pid:66807)
[2018-06-06 15:30:43 -0700] [50067] [CRITICAL] WORKER TIMEOUT (pid:66808)
[2018-06-06 15:30:43 -0700] [50067] [CRITICAL] WORKER TIMEOUT (pid:66797)
[2018-06-06 15:30:43 -0700] [50067] [CRITICAL] WORKER TIMEOUT (pid:66802)
[2018-06-06 15:30:43 -0700] [50067] [CRITICAL] WORKER TIMEOUT (pid:66805)
[2018-06-06 15:30:43 -0700] [50067] [CRITICAL] WORKER TIMEOUT (pid:66806)
[2018-06-06 15:32:33 -0700] [50067] [CRITICAL] WORKER TIMEOUT (pid:67136)
[2018-06-06 15:32:33 -0700] [50067] [CRITICAL] WORKER TIMEOUT (pid:67137)
[2018-06-06 15:32:33 -0700] [50067] [CRITICAL] WORKER TIMEOUT (pid:67138)
[2018-06-06 15:32:33 -0700] [50067] [CRITICAL] WORKER TIMEOUT (pid:67139)
[2018-06-06 15:32:33 -0700] [50067] [CRITICAL] WORKER TIMEOUT (pid:67140)
[2018-06-06 15:32:33 -0700] [50067] [CRITICAL] WORKER TIMEOUT (pid:67141)
[2018-06-06 15:32:33 -0700] [50067] [CRITICAL] WORKER TIMEOUT (pid:67142)
[2018-06-06 15:32:33 -0700] [50067] [CRITICAL] WORKER TIMEOUT (pid:67143)
[2018-06-06 15:32:33 -0700] [50067] [CRITICAL] WORKER TIMEOUT (pid:67144)
[2018-06-06 15:32:33 -0700] [50067] [CRITICAL] WORKER TIMEOUT (pid:67145)
[2018-06-06 15:32:33 -0700] [50067] [CRITICAL] WORKER TIMEOUT (pid:67146)
[2018-06-06 15:32:33 -0700] [50067] [CRITICAL] WORKER TIMEOUT (pid:67127)
[2018-06-06 15:32:33 -0700] [50067] [CRITICAL] WORKER TIMEOUT (pid:67147)
[2018-06-06 15:32:33 -0700] [50067] [CRITICAL] WORKER TIMEOUT (pid:67152)
[2018-06-06 15:32:33 -0700] [50067] [CRITICAL] WORKER TIMEOUT (pid:67148)
[2018-06-06 15:32:33 -0700] [50067] [CRITICAL] WORKER TIMEOUT (pid:67134)
[2018-06-06 15:32:33 -0700] [50067] [CRITICAL] WORKER TIMEOUT (pid:67135)
[2018-06-06 18:34:57 -0700] [50067] [CRITICAL] WORKER TIMEOUT (pid:67328)
[2018-06-06 18:34:57 -0700] [50067] [CRITICAL] WORKER TIMEOUT (pid:67329)
[2018-06-06 18:34:57 -0700] [50067] [CRITICAL] WORKER TIMEOUT (pid:67330)
[2018-06-06 18:34:57 -0700] [50067] [CRITICAL] WORKER TIMEOUT (pid:67331)
[2018-06-06 18:34:57 -0700] [50067] [CRITICAL] WORKER TIMEOUT (pid:67332)
[2018-06-06 18:34:57 -0700] [50067] [CRITICAL] WORKER TIMEOUT (pid:67333)
[2018-06-06 18:34:57 -0700] [50067] [CRITICAL] WORKER TIMEOUT (pid:67334)
[2018-06-06 18:34:57 -0700] [50067] [CRITICAL] WORKER TIMEOUT (pid:67335)
[2018-06-06 18:34:57 -0700] [50067] [CRITICAL] WORKER TIMEOUT (pid:67336)
[2018-06-06 18:34:57 -0700] [50067] [CRITICAL] WORKER TIMEOUT (pid:67338)
[2018-06-06 18:34:57 -0700] [50067] [CRITICAL] WORKER TIMEOUT (pid:67339)
[2018-06-06 18:34:57 -0700] [50067] [CRITICAL] WORKER TIMEOUT (pid:67340)
[2018-06-06 18:34:57 -0700] [50067] [CRITICAL] WORKER TIMEOUT (pid:67341)
[2018-06-06 18:34:57 -0700] [50067] [CRITICAL] WORKER TIMEOUT (pid:67326)
[2018-06-06 18:34:57 -0700] [50067] [CRITICAL] WORKER TIMEOUT (pid:67324)
[2018-06-06 18:34:57 -0700] [50067] [CRITICAL] WORKER TIMEOUT (pid:67325)
[2018-06-06 18:34:57 -0700] [50067] [CRITICAL] WORKER TIMEOUT (pid:67327)
[2018-06-06 18:38:15 -0700] [50067] [CRITICAL] WORKER TIMEOUT (pid:84272)
[2018-06-06 18:38:15 -0700] [50067] [CRITICAL] WORKER TIMEOUT (pid:84273)
[2018-06-06 18:38:15 -0700] [50067] [CRITICAL] WORKER TIMEOUT (pid:84274)
[2018-06-06 18:38:15 -0700] [50067] [CRITICAL] WORKER TIMEOUT (pid:84275)
[2018-06-06 18:38:15 -0700] [50067] [CRITICAL] WORKER TIMEOUT (pid:84277)
[2018-06-06 18:38:15 -0700] [50067] [CRITICAL] WORKER TIMEOUT (pid:84278)
[2018-06-06 18:38:15 -0700] [50067] [CRITICAL] WORKER TIMEOUT (pid:84279)
[2018-06-06 18:38:15 -0700] [50067] [CRITICAL] WORKER TIMEOUT (pid:84280)
[2018-06-06 18:38:15 -0700] [50067] [CRITICAL] WORKER TIMEOUT (pid:84281)
[2018-06-06 18:38:15 -0700] [50067] [CRITICAL] WORKER TIMEOUT (pid:84282)
[2018-06-06 18:38:15 -0700] [50067] [CRITICAL] WORKER TIMEOUT (pid:84283)
[2018-06-06 18:38:15 -0700] [50067] [CRITICAL] WORKER TIMEOUT (pid:84284)
[2018-06-06 18:38:15 -0700] [50067] [CRITICAL] WORKER TIMEOUT (pid:84288)
[2018-06-06 18:38:15 -0700] [50067] [CRITICAL] WORKER TIMEOUT (pid:84276)
[2018-06-06 18:38:15 -0700] [50067] [CRITICAL] WORKER TIMEOUT (pid:84285)
[2018-06-06 18:38:15 -0700] [50067] [CRITICAL] WORKER TIMEOUT (pid:84286)
[2018-06-06 18:38:15 -0700] [50067] [CRITICAL] WORKER TIMEOUT (pid:84287)
[2018-06-06 18:59:04 -0700] [50067] [CRITICAL] WORKER TIMEOUT (pid:84800)
[2018-06-06 18:59:04 -0700] [50067] [CRITICAL] WORKER TIMEOUT (pid:84801)
[2018-06-06 18:59:04 -0700] [50067] [CRITICAL] WORKER TIMEOUT (pid:84802)
[2018-06-06 18:59:04 -0700] [50067] [CRITICAL] WORKER TIMEOUT (pid:84803)
[2018-06-06 18:59:04 -0700] [50067] [CRITICAL] WORKER TIMEOUT (pid:84804)
[2018-06-06 18:59:04 -0700] [50067] [CRITICAL] WORKER TIMEOUT (pid:84805)
[2018-06-06 18:59:04 -0700] [50067] [CRITICAL] WORKER TIMEOUT (pid:84806)
[2018-06-06 18:59:04 -0700] [50067] [CRITICAL] WORKER TIMEOUT (pid:84807)
[2018-06-06 18:59:04 -0700] [50067] [CRITICAL] WORKER TIMEOUT (pid:84808)
[2018-06-06 18:59:04 -0700] [50067] [CRITICAL] WORKER TIMEOUT (pid:84809)
[2018-06-06 18:59:04 -0700] [50067] [CRITICAL] WORKER TIMEOUT (pid:84810)
[2018-06-06 18:59:04 -0700] [50067] [CRITICAL] WORKER TIMEOUT (pid:84811)
[2018-06-06 18:59:04 -0700] [50067] [CRITICAL] WORKER TIMEOUT (pid:84812)
[2018-06-06 18:59:04 -0700] [50067] [CRITICAL] WORKER TIMEOUT (pid:84813)
[2018-06-06 18:59:04 -0700] [50067] [CRITICAL] WORKER TIMEOUT (pid:84814)
[2018-06-06 18:59:04 -0700] [50067] [CRITICAL] WORKER TIMEOUT (pid:84798)
[2018-06-06 18:59:04 -0700] [50067] [CRITICAL] WORKER TIMEOUT (pid:84799)
[2018-06-06 18:59:04 -0700] [84943] [ERROR] Exception in worker process:
Traceback (most recent call last):
  File "/usr/local/lib/python2.7/site-packages/gunicorn/arbiter.py", line 515, in spawn_worker
    worker.init_process()
  File "/usr/local/lib/python2.7/site-packages/gunicorn/workers/base.py", line 122, in init_process
    self.load_wsgi()
  File "/usr/local/lib/python2.7/site-packages/gunicorn/workers/base.py", line 130, in load_wsgi
    self.wsgi = self.app.wsgi()
  File "/usr/local/lib/python2.7/site-packages/gunicorn/app/base.py", line 67, in wsgi
    self.callable = self.load()
  File "/usr/local/lib/python2.7/site-packages/psiturk/experiment_server.py", line 47, in load
    return util.import_app("psiturk.experiment:app")
  File "/usr/local/lib/python2.7/site-packages/gunicorn/util.py", line 357, in import_app
    __import__(module)
  File "/usr/local/lib/python2.7/site-packages/psiturk/experiment.py", line 89, in <module>
    init_db()
  File "/usr/local/lib/python2.7/site-packages/psiturk/db.py", line 37, in init_db
    Base.metadata.create_all(bind=engine)
  File "/usr/local/lib/python2.7/site-packages/sqlalchemy/schema.py", line 2848, in create_all
    tables=tables)
  File "/usr/local/lib/python2.7/site-packages/sqlalchemy/engine/base.py", line 1478, in _run_visitor
    with self._optional_conn_ctx_manager(connection) as conn:
  File "/usr/local/Cellar/python@2/2.7.15/Frameworks/Python.framework/Versions/2.7/lib/python2.7/contextlib.py", line 17, in __enter__
    return self.gen.next()
  File "/usr/local/lib/python2.7/site-packages/sqlalchemy/engine/base.py", line 1471, in _optional_conn_ctx_manager
    with self.contextual_connect() as conn:
  File "/usr/local/lib/python2.7/site-packages/sqlalchemy/engine/base.py", line 1661, in contextual_connect
    self.pool.connect(),
  File "/usr/local/lib/python2.7/site-packages/sqlalchemy/pool.py", line 272, in connect
    return _ConnectionFairy(self).checkout()
  File "/usr/local/lib/python2.7/site-packages/sqlalchemy/pool.py", line 431, in __init__
    rec = self._connection_record = pool._do_get()
  File "/usr/local/lib/python2.7/site-packages/sqlalchemy/pool.py", line 788, in _do_get
    con = self._create_connection()
  File "/usr/local/lib/python2.7/site-packages/sqlalchemy/pool.py", line 225, in _create_connection
    return _ConnectionRecord(self)
  File "/usr/local/lib/python2.7/site-packages/sqlalchemy/pool.py", line 318, in __init__
    self.connection = self.__connect()
  File "/usr/local/lib/python2.7/site-packages/sqlalchemy/pool.py", line 379, in __connect
    connection = self.__pool._creator()
  File "/usr/local/lib/python2.7/site-packages/sqlalchemy/engine/strategies.py", line 80, in connect
    return dialect.connect(*cargs, **cparams)
  File "/usr/local/lib/python2.7/site-packages/sqlalchemy/engine/default.py", line 283, in connect
    return self.dbapi.connect(*cargs, **cparams)
  File "/usr/local/lib/python2.7/site-packages/psycopg2/__init__.py", line 130, in connect
    conn = _connect(dsn, connection_factory=connection_factory, **kwasync)
OperationalError: (OperationalError) could not connect to server: Network is down
	Is the server running on host "ec2-23-21-129-50.compute-1.amazonaws.com" (23.21.129.50) and accepting
	TCP/IP connections on port 5432?
 None None
Traceback (most recent call last):
  File "/usr/local/lib/python2.7/site-packages/gunicorn/arbiter.py", line 515, in spawn_worker
    worker.init_process()
  File "/usr/local/lib/python2.7/site-packages/gunicorn/workers/base.py", line 122, in init_process
    self.load_wsgi()
  File "/usr/local/lib/python2.7/site-packages/gunicorn/workers/base.py", line 130, in load_wsgi
    self.wsgi = self.app.wsgi()
  File "/usr/local/lib/python2.7/site-packages/gunicorn/app/base.py", line 67, in wsgi
    self.callable = self.load()
  File "/usr/local/lib/python2.7/site-packages/psiturk/experiment_server.py", line 47, in load
    return util.import_app("psiturk.experiment:app")
  File "/usr/local/lib/python2.7/site-packages/gunicorn/util.py", line 357, in import_app
    __import__(module)
  File "/usr/local/lib/python2.7/site-packages/psiturk/experiment.py", line 89, in <module>
    init_db()
  File "/usr/local/lib/python2.7/site-packages/psiturk/db.py", line 37, in init_db
    Base.metadata.create_all(bind=engine)
  File "/usr/local/lib/python2.7/site-packages/sqlalchemy/schema.py", line 2848, in create_all
    tables=tables)
  File "/usr/local/lib/python2.7/site-packages/sqlalchemy/engine/base.py", line 1478, in _run_visitor
    with self._optional_conn_ctx_manager(connection) as conn:
  File "/usr/local/Cellar/python@2/2.7.15/Frameworks/Python.framework/Versions/2.7/lib/python2.7/contextlib.py", line 17, in __enter__
    return self.gen.next()
  File "/usr/local/lib/python2.7/site-packages/sqlalchemy/engine/base.py", line 1471, in _optional_conn_ctx_manager
    with self.contextual_connect() as conn:
  File "/usr/local/lib/python2.7/site-packages/sqlalchemy/engine/base.py", line 1661, in contextual_connect
    self.pool.connect(),
  File "/usr/local/lib/python2.7/site-packages/sqlalchemy/pool.py", line 272, in connect
    return _ConnectionFairy(self).checkout()
  File "/usr/local/lib/python2.7/site-packages/sqlalchemy/pool.py", line 431, in __init__
    rec = self._connection_record = pool._do_get()
  File "/usr/local/lib/python2.7/site-packages/sqlalchemy/pool.py", line 788, in _do_get
    con = self._create_connection()
  File "/usr/local/lib/python2.7/site-packages/sqlalchemy/pool.py", line 225, in _create_connection
    return _ConnectionRecord(self)
  File "/usr/local/lib/python2.7/site-packages/sqlalchemy/pool.py", line 318, in __init__
    self.connection = self.__connect()
  File "/usr/local/lib/python2.7/site-packages/sqlalchemy/pool.py", line 379, in __connect
    connection = self.__pool._creator()
  File "/usr/local/lib/python2.7/site-packages/sqlalchemy/engine/strategies.py", line 80, in connect
    return dialect.connect(*cargs, **cparams)
  File "/usr/local/lib/python2.7/site-packages/sqlalchemy/engine/default.py", line 283, in connect
    return self.dbapi.connect(*cargs, **cparams)
  File "/usr/local/lib/python2.7/site-packages/psycopg2/__init__.py", line 130, in connect
    conn = _connect(dsn, connection_factory=connection_factory, **kwasync)
OperationalError: (OperationalError) could not connect to server: Network is down
	Is the server running on host "ec2-23-21-129-50.compute-1.amazonaws.com" (23.21.129.50) and accepting
	TCP/IP connections on port 5432?
 None None
[2018-06-06 18:59:04 -0700] [84944] [ERROR] Exception in worker process:
Traceback (most recent call last):
  File "/usr/local/lib/python2.7/site-packages/gunicorn/arbiter.py", line 515, in spawn_worker
    worker.init_process()
  File "/usr/local/lib/python2.7/site-packages/gunicorn/workers/base.py", line 122, in init_process
    self.load_wsgi()
  File "/usr/local/lib/python2.7/site-packages/gunicorn/workers/base.py", line 130, in load_wsgi
    self.wsgi = self.app.wsgi()
  File "/usr/local/lib/python2.7/site-packages/gunicorn/app/base.py", line 67, in wsgi
    self.callable = self.load()
  File "/usr/local/lib/python2.7/site-packages/psiturk/experiment_server.py", line 47, in load
    return util.import_app("psiturk.experiment:app")
  File "/usr/local/lib/python2.7/site-packages/gunicorn/util.py", line 357, in import_app
    __import__(module)
  File "/usr/local/lib/python2.7/site-packages/psiturk/experiment.py", line 89, in <module>
    init_db()
  File "/usr/local/lib/python2.7/site-packages/psiturk/db.py", line 37, in init_db
    Base.metadata.create_all(bind=engine)
  File "/usr/local/lib/python2.7/site-packages/sqlalchemy/schema.py", line 2848, in create_all
    tables=tables)
  File "/usr/local/lib/python2.7/site-packages/sqlalchemy/engine/base.py", line 1478, in _run_visitor
    with self._optional_conn_ctx_manager(connection) as conn:
  File "/usr/local/Cellar/python@2/2.7.15/Frameworks/Python.framework/Versions/2.7/lib/python2.7/contextlib.py", line 17, in __enter__
    return self.gen.next()
  File "/usr/local/lib/python2.7/site-packages/sqlalchemy/engine/base.py", line 1471, in _optional_conn_ctx_manager
    with self.contextual_connect() as conn:
  File "/usr/local/lib/python2.7/site-packages/sqlalchemy/engine/base.py", line 1661, in contextual_connect
    self.pool.connect(),
  File "/usr/local/lib/python2.7/site-packages/sqlalchemy/pool.py", line 272, in connect
    return _ConnectionFairy(self).checkout()
  File "/usr/local/lib/python2.7/site-packages/sqlalchemy/pool.py", line 431, in __init__
    rec = self._connection_record = pool._do_get()
  File "/usr/local/lib/python2.7/site-packages/sqlalchemy/pool.py", line 788, in _do_get
    con = self._create_connection()
  File "/usr/local/lib/python2.7/site-packages/sqlalchemy/pool.py", line 225, in _create_connection
    return _ConnectionRecord(self)
  File "/usr/local/lib/python2.7/site-packages/sqlalchemy/pool.py", line 318, in __init__
    self.connection = self.__connect()
  File "/usr/local/lib/python2.7/site-packages/sqlalchemy/pool.py", line 379, in __connect
    connection = self.__pool._creator()
  File "/usr/local/lib/python2.7/site-packages/sqlalchemy/engine/strategies.py", line 80, in connect
    return dialect.connect(*cargs, **cparams)
  File "/usr/local/lib/python2.7/site-packages/sqlalchemy/engine/default.py", line 283, in connect
    return self.dbapi.connect(*cargs, **cparams)
  File "/usr/local/lib/python2.7/site-packages/psycopg2/__init__.py", line 130, in connect
    conn = _connect(dsn, connection_factory=connection_factory, **kwasync)
OperationalError: (OperationalError) could not connect to server: Network is down
	Is the server running on host "ec2-23-21-129-50.compute-1.amazonaws.com" (23.21.129.50) and accepting
	TCP/IP connections on port 5432?
 None None
Traceback (most recent call last):
  File "/usr/local/lib/python2.7/site-packages/gunicorn/arbiter.py", line 515, in spawn_worker
    worker.init_process()
  File "/usr/local/lib/python2.7/site-packages/gunicorn/workers/base.py", line 122, in init_process
    self.load_wsgi()
  File "/usr/local/lib/python2.7/site-packages/gunicorn/workers/base.py", line 130, in load_wsgi
    self.wsgi = self.app.wsgi()
  File "/usr/local/lib/python2.7/site-packages/gunicorn/app/base.py", line 67, in wsgi
    self.callable = self.load()
  File "/usr/local/lib/python2.7/site-packages/psiturk/experiment_server.py", line 47, in load
    return util.import_app("psiturk.experiment:app")
  File "/usr/local/lib/python2.7/site-packages/gunicorn/util.py", line 357, in import_app
    __import__(module)
  File "/usr/local/lib/python2.7/site-packages/psiturk/experiment.py", line 89, in <module>
    init_db()
  File "/usr/local/lib/python2.7/site-packages/psiturk/db.py", line 37, in init_db
    Base.metadata.create_all(bind=engine)
  File "/usr/local/lib/python2.7/site-packages/sqlalchemy/schema.py", line 2848, in create_all
    tables=tables)
  File "/usr/local/lib/python2.7/site-packages/sqlalchemy/engine/base.py", line 1478, in _run_visitor
    with self._optional_conn_ctx_manager(connection) as conn:
  File "/usr/local/Cellar/python@2/2.7.15/Frameworks/Python.framework/Versions/2.7/lib/python2.7/contextlib.py", line 17, in __enter__
    return self.gen.next()
  File "/usr/local/lib/python2.7/site-packages/sqlalchemy/engine/base.py", line 1471, in _optional_conn_ctx_manager
    with self.contextual_connect() as conn:
  File "/usr/local/lib/python2.7/site-packages/sqlalchemy/engine/base.py", line 1661, in contextual_connect
    self.pool.connect(),
  File "/usr/local/lib/python2.7/site-packages/sqlalchemy/pool.py", line 272, in connect
    return _ConnectionFairy(self).checkout()
  File "/usr/local/lib/python2.7/site-packages/sqlalchemy/pool.py", line 431, in __init__
    rec = self._connection_record = pool._do_get()
  File "/usr/local/lib/python2.7/site-packages/sqlalchemy/pool.py", line 788, in _do_get
    con = self._create_connection()
  File "/usr/local/lib/python2.7/site-packages/sqlalchemy/pool.py", line 225, in _create_connection
    return _ConnectionRecord(self)
  File "/usr/local/lib/python2.7/site-packages/sqlalchemy/pool.py", line 318, in __init__
    self.connection = self.__connect()
  File "/usr/local/lib/python2.7/site-packages/sqlalchemy/pool.py", line 379, in __connect
    connection = self.__pool._creator()
  File "/usr/local/lib/python2.7/site-packages/sqlalchemy/engine/strategies.py", line 80, in connect
    return dialect.connect(*cargs, **cparams)
  File "/usr/local/lib/python2.7/site-packages/sqlalchemy/engine/default.py", line 283, in connect
    return self.dbapi.connect(*cargs, **cparams)
  File "/usr/local/lib/python2.7/site-packages/psycopg2/__init__.py", line 130, in connect
    conn = _connect(dsn, connection_factory=connection_factory, **kwasync)
OperationalError: (OperationalError) could not connect to server: Network is down
	Is the server running on host "ec2-23-21-129-50.compute-1.amazonaws.com" (23.21.129.50) and accepting
	TCP/IP connections on port 5432?
 None None
[2018-06-06 18:59:04 -0700] [84945] [ERROR] Exception in worker process:
Traceback (most recent call last):
  File "/usr/local/lib/python2.7/site-packages/gunicorn/arbiter.py", line 515, in spawn_worker
    worker.init_process()
  File "/usr/local/lib/python2.7/site-packages/gunicorn/workers/base.py", line 122, in init_process
    self.load_wsgi()
  File "/usr/local/lib/python2.7/site-packages/gunicorn/workers/base.py", line 130, in load_wsgi
    self.wsgi = self.app.wsgi()
  File "/usr/local/lib/python2.7/site-packages/gunicorn/app/base.py", line 67, in wsgi
    self.callable = self.load()
  File "/usr/local/lib/python2.7/site-packages/psiturk/experiment_server.py", line 47, in load
    return util.import_app("psiturk.experiment:app")
  File "/usr/local/lib/python2.7/site-packages/gunicorn/util.py", line 357, in import_app
    __import__(module)
  File "/usr/local/lib/python2.7/site-packages/psiturk/experiment.py", line 89, in <module>
    init_db()
  File "/usr/local/lib/python2.7/site-packages/psiturk/db.py", line 37, in init_db
    Base.metadata.create_all(bind=engine)
  File "/usr/local/lib/python2.7/site-packages/sqlalchemy/schema.py", line 2848, in create_all
    tables=tables)
  File "/usr/local/lib/python2.7/site-packages/sqlalchemy/engine/base.py", line 1478, in _run_visitor
    with self._optional_conn_ctx_manager(connection) as conn:
  File "/usr/local/Cellar/python@2/2.7.15/Frameworks/Python.framework/Versions/2.7/lib/python2.7/contextlib.py", line 17, in __enter__
    return self.gen.next()
  File "/usr/local/lib/python2.7/site-packages/sqlalchemy/engine/base.py", line 1471, in _optional_conn_ctx_manager
    with self.contextual_connect() as conn:
  File "/usr/local/lib/python2.7/site-packages/sqlalchemy/engine/base.py", line 1661, in contextual_connect
    self.pool.connect(),
  File "/usr/local/lib/python2.7/site-packages/sqlalchemy/pool.py", line 272, in connect
    return _ConnectionFairy(self).checkout()
  File "/usr/local/lib/python2.7/site-packages/sqlalchemy/pool.py", line 431, in __init__
    rec = self._connection_record = pool._do_get()
  File "/usr/local/lib/python2.7/site-packages/sqlalchemy/pool.py", line 788, in _do_get
    con = self._create_connection()
  File "/usr/local/lib/python2.7/site-packages/sqlalchemy/pool.py", line 225, in _create_connection
    return _ConnectionRecord(self)
  File "/usr/local/lib/python2.7/site-packages/sqlalchemy/pool.py", line 318, in __init__
    self.connection = self.__connect()
  File "/usr/local/lib/python2.7/site-packages/sqlalchemy/pool.py", line 379, in __connect
    connection = self.__pool._creator()
  File "/usr/local/lib/python2.7/site-packages/sqlalchemy/engine/strategies.py", line 80, in connect
    return dialect.connect(*cargs, **cparams)
  File "/usr/local/lib/python2.7/site-packages/sqlalchemy/engine/default.py", line 283, in connect
    return self.dbapi.connect(*cargs, **cparams)
  File "/usr/local/lib/python2.7/site-packages/psycopg2/__init__.py", line 130, in connect
    conn = _connect(dsn, connection_factory=connection_factory, **kwasync)
OperationalError: (OperationalError) could not connect to server: Network is down
	Is the server running on host "ec2-23-21-129-50.compute-1.amazonaws.com" (23.21.129.50) and accepting
	TCP/IP connections on port 5432?
 None None
Traceback (most recent call last):
  File "/usr/local/lib/python2.7/site-packages/gunicorn/arbiter.py", line 515, in spawn_worker
    worker.init_process()
  File "/usr/local/lib/python2.7/site-packages/gunicorn/workers/base.py", line 122, in init_process
    self.load_wsgi()
  File "/usr/local/lib/python2.7/site-packages/gunicorn/workers/base.py", line 130, in load_wsgi
    self.wsgi = self.app.wsgi()
  File "/usr/local/lib/python2.7/site-packages/gunicorn/app/base.py", line 67, in wsgi
    self.callable = self.load()
  File "/usr/local/lib/python2.7/site-packages/psiturk/experiment_server.py", line 47, in load
    return util.import_app("psiturk.experiment:app")
  File "/usr/local/lib/python2.7/site-packages/gunicorn/util.py", line 357, in import_app
    __import__(module)
  File "/usr/local/lib/python2.7/site-packages/psiturk/experiment.py", line 89, in <module>
    init_db()
  File "/usr/local/lib/python2.7/site-packages/psiturk/db.py", line 37, in init_db
    Base.metadata.create_all(bind=engine)
  File "/usr/local/lib/python2.7/site-packages/sqlalchemy/schema.py", line 2848, in create_all
    tables=tables)
  File "/usr/local/lib/python2.7/site-packages/sqlalchemy/engine/base.py", line 1478, in _run_visitor
    with self._optional_conn_ctx_manager(connection) as conn:
  File "/usr/local/Cellar/python@2/2.7.15/Frameworks/Python.framework/Versions/2.7/lib/python2.7/contextlib.py", line 17, in __enter__
    return self.gen.next()
  File "/usr/local/lib/python2.7/site-packages/sqlalchemy/engine/base.py", line 1471, in _optional_conn_ctx_manager
    with self.contextual_connect() as conn:
  File "/usr/local/lib/python2.7/site-packages/sqlalchemy/engine/base.py", line 1661, in contextual_connect
    self.pool.connect(),
  File "/usr/local/lib/python2.7/site-packages/sqlalchemy/pool.py", line 272, in connect
    return _ConnectionFairy(self).checkout()
  File "/usr/local/lib/python2.7/site-packages/sqlalchemy/pool.py", line 431, in __init__
    rec = self._connection_record = pool._do_get()
  File "/usr/local/lib/python2.7/site-packages/sqlalchemy/pool.py", line 788, in _do_get
    con = self._create_connection()
  File "/usr/local/lib/python2.7/site-packages/sqlalchemy/pool.py", line 225, in _create_connection
    return _ConnectionRecord(self)
  File "/usr/local/lib/python2.7/site-packages/sqlalchemy/pool.py", line 318, in __init__
    self.connection = self.__connect()
  File "/usr/local/lib/python2.7/site-packages/sqlalchemy/pool.py", line 379, in __connect
    connection = self.__pool._creator()
  File "/usr/local/lib/python2.7/site-packages/sqlalchemy/engine/strategies.py", line 80, in connect
    return dialect.connect(*cargs, **cparams)
  File "/usr/local/lib/python2.7/site-packages/sqlalchemy/engine/default.py", line 283, in connect
    return self.dbapi.connect(*cargs, **cparams)
  File "/usr/local/lib/python2.7/site-packages/psycopg2/__init__.py", line 130, in connect
    conn = _connect(dsn, connection_factory=connection_factory, **kwasync)
OperationalError: (OperationalError) could not connect to server: Network is down
	Is the server running on host "ec2-23-21-129-50.compute-1.amazonaws.com" (23.21.129.50) and accepting
	TCP/IP connections on port 5432?
 None None
[2018-06-06 18:59:05 -0700] [84946] [ERROR] Exception in worker process:
Traceback (most recent call last):
  File "/usr/local/lib/python2.7/site-packages/gunicorn/arbiter.py", line 515, in spawn_worker
    worker.init_process()
  File "/usr/local/lib/python2.7/site-packages/gunicorn/workers/base.py", line 122, in init_process
    self.load_wsgi()
  File "/usr/local/lib/python2.7/site-packages/gunicorn/workers/base.py", line 130, in load_wsgi
    self.wsgi = self.app.wsgi()
  File "/usr/local/lib/python2.7/site-packages/gunicorn/app/base.py", line 67, in wsgi
    self.callable = self.load()
  File "/usr/local/lib/python2.7/site-packages/psiturk/experiment_server.py", line 47, in load
    return util.import_app("psiturk.experiment:app")
  File "/usr/local/lib/python2.7/site-packages/gunicorn/util.py", line 357, in import_app
    __import__(module)
  File "/usr/local/lib/python2.7/site-packages/psiturk/experiment.py", line 89, in <module>
    init_db()
  File "/usr/local/lib/python2.7/site-packages/psiturk/db.py", line 37, in init_db
    Base.metadata.create_all(bind=engine)
  File "/usr/local/lib/python2.7/site-packages/sqlalchemy/schema.py", line 2848, in create_all
    tables=tables)
  File "/usr/local/lib/python2.7/site-packages/sqlalchemy/engine/base.py", line 1478, in _run_visitor
    with self._optional_conn_ctx_manager(connection) as conn:
  File "/usr/local/Cellar/python@2/2.7.15/Frameworks/Python.framework/Versions/2.7/lib/python2.7/contextlib.py", line 17, in __enter__
    return self.gen.next()
  File "/usr/local/lib/python2.7/site-packages/sqlalchemy/engine/base.py", line 1471, in _optional_conn_ctx_manager
    with self.contextual_connect() as conn:
  File "/usr/local/lib/python2.7/site-packages/sqlalchemy/engine/base.py", line 1661, in contextual_connect
    self.pool.connect(),
  File "/usr/local/lib/python2.7/site-packages/sqlalchemy/pool.py", line 272, in connect
    return _ConnectionFairy(self).checkout()
  File "/usr/local/lib/python2.7/site-packages/sqlalchemy/pool.py", line 431, in __init__
    rec = self._connection_record = pool._do_get()
  File "/usr/local/lib/python2.7/site-packages/sqlalchemy/pool.py", line 788, in _do_get
    con = self._create_connection()
  File "/usr/local/lib/python2.7/site-packages/sqlalchemy/pool.py", line 225, in _create_connection
    return _ConnectionRecord(self)
  File "/usr/local/lib/python2.7/site-packages/sqlalchemy/pool.py", line 318, in __init__
    self.connection = self.__connect()
  File "/usr/local/lib/python2.7/site-packages/sqlalchemy/pool.py", line 379, in __connect
    connection = self.__pool._creator()
  File "/usr/local/lib/python2.7/site-packages/sqlalchemy/engine/strategies.py", line 80, in connect
    return dialect.connect(*cargs, **cparams)
  File "/usr/local/lib/python2.7/site-packages/sqlalchemy/engine/default.py", line 283, in connect
    return self.dbapi.connect(*cargs, **cparams)
  File "/usr/local/lib/python2.7/site-packages/psycopg2/__init__.py", line 130, in connect
    conn = _connect(dsn, connection_factory=connection_factory, **kwasync)
OperationalError: (OperationalError) could not connect to server: Network is down
	Is the server running on host "ec2-23-21-129-50.compute-1.amazonaws.com" (23.21.129.50) and accepting
	TCP/IP connections on port 5432?
 None None
Traceback (most recent call last):
  File "/usr/local/lib/python2.7/site-packages/gunicorn/arbiter.py", line 515, in spawn_worker
    worker.init_process()
  File "/usr/local/lib/python2.7/site-packages/gunicorn/workers/base.py", line 122, in init_process
    self.load_wsgi()
  File "/usr/local/lib/python2.7/site-packages/gunicorn/workers/base.py", line 130, in load_wsgi
    self.wsgi = self.app.wsgi()
  File "/usr/local/lib/python2.7/site-packages/gunicorn/app/base.py", line 67, in wsgi
    self.callable = self.load()
  File "/usr/local/lib/python2.7/site-packages/psiturk/experiment_server.py", line 47, in load
    return util.import_app("psiturk.experiment:app")
  File "/usr/local/lib/python2.7/site-packages/gunicorn/util.py", line 357, in import_app
    __import__(module)
  File "/usr/local/lib/python2.7/site-packages/psiturk/experiment.py", line 89, in <module>
    init_db()
  File "/usr/local/lib/python2.7/site-packages/psiturk/db.py", line 37, in init_db
    Base.metadata.create_all(bind=engine)
  File "/usr/local/lib/python2.7/site-packages/sqlalchemy/schema.py", line 2848, in create_all
    tables=tables)
  File "/usr/local/lib/python2.7/site-packages/sqlalchemy/engine/base.py", line 1478, in _run_visitor
    with self._optional_conn_ctx_manager(connection) as conn:
  File "/usr/local/Cellar/python@2/2.7.15/Frameworks/Python.framework/Versions/2.7/lib/python2.7/contextlib.py", line 17, in __enter__
    return self.gen.next()
  File "/usr/local/lib/python2.7/site-packages/sqlalchemy/engine/base.py", line 1471, in _optional_conn_ctx_manager
    with self.contextual_connect() as conn:
  File "/usr/local/lib/python2.7/site-packages/sqlalchemy/engine/base.py", line 1661, in contextual_connect
    self.pool.connect(),
  File "/usr/local/lib/python2.7/site-packages/sqlalchemy/pool.py", line 272, in connect
    return _ConnectionFairy(self).checkout()
  File "/usr/local/lib/python2.7/site-packages/sqlalchemy/pool.py", line 431, in __init__
    rec = self._connection_record = pool._do_get()
  File "/usr/local/lib/python2.7/site-packages/sqlalchemy/pool.py", line 788, in _do_get
    con = self._create_connection()
  File "/usr/local/lib/python2.7/site-packages/sqlalchemy/pool.py", line 225, in _create_connection
    return _ConnectionRecord(self)
  File "/usr/local/lib/python2.7/site-packages/sqlalchemy/pool.py", line 318, in __init__
    self.connection = self.__connect()
  File "/usr/local/lib/python2.7/site-packages/sqlalchemy/pool.py", line 379, in __connect
    connection = self.__pool._creator()
  File "/usr/local/lib/python2.7/site-packages/sqlalchemy/engine/strategies.py", line 80, in connect
    return dialect.connect(*cargs, **cparams)
  File "/usr/local/lib/python2.7/site-packages/sqlalchemy/engine/default.py", line 283, in connect
    return self.dbapi.connect(*cargs, **cparams)
  File "/usr/local/lib/python2.7/site-packages/psycopg2/__init__.py", line 130, in connect
    conn = _connect(dsn, connection_factory=connection_factory, **kwasync)
OperationalError: (OperationalError) could not connect to server: Network is down
	Is the server running on host "ec2-23-21-129-50.compute-1.amazonaws.com" (23.21.129.50) and accepting
	TCP/IP connections on port 5432?
 None None
[2018-06-06 18:59:05 -0700] [84947] [ERROR] Exception in worker process:
Traceback (most recent call last):
  File "/usr/local/lib/python2.7/site-packages/gunicorn/arbiter.py", line 515, in spawn_worker
    worker.init_process()
  File "/usr/local/lib/python2.7/site-packages/gunicorn/workers/base.py", line 122, in init_process
    self.load_wsgi()
  File "/usr/local/lib/python2.7/site-packages/gunicorn/workers/base.py", line 130, in load_wsgi
    self.wsgi = self.app.wsgi()
  File "/usr/local/lib/python2.7/site-packages/gunicorn/app/base.py", line 67, in wsgi
    self.callable = self.load()
  File "/usr/local/lib/python2.7/site-packages/psiturk/experiment_server.py", line 47, in load
    return util.import_app("psiturk.experiment:app")
  File "/usr/local/lib/python2.7/site-packages/gunicorn/util.py", line 357, in import_app
    __import__(module)
  File "/usr/local/lib/python2.7/site-packages/psiturk/experiment.py", line 89, in <module>
    init_db()
  File "/usr/local/lib/python2.7/site-packages/psiturk/db.py", line 37, in init_db
    Base.metadata.create_all(bind=engine)
  File "/usr/local/lib/python2.7/site-packages/sqlalchemy/schema.py", line 2848, in create_all
    tables=tables)
  File "/usr/local/lib/python2.7/site-packages/sqlalchemy/engine/base.py", line 1478, in _run_visitor
    with self._optional_conn_ctx_manager(connection) as conn:
  File "/usr/local/Cellar/python@2/2.7.15/Frameworks/Python.framework/Versions/2.7/lib/python2.7/contextlib.py", line 17, in __enter__
    return self.gen.next()
  File "/usr/local/lib/python2.7/site-packages/sqlalchemy/engine/base.py", line 1471, in _optional_conn_ctx_manager
    with self.contextual_connect() as conn:
  File "/usr/local/lib/python2.7/site-packages/sqlalchemy/engine/base.py", line 1661, in contextual_connect
    self.pool.connect(),
  File "/usr/local/lib/python2.7/site-packages/sqlalchemy/pool.py", line 272, in connect
    return _ConnectionFairy(self).checkout()
  File "/usr/local/lib/python2.7/site-packages/sqlalchemy/pool.py", line 431, in __init__
    rec = self._connection_record = pool._do_get()
  File "/usr/local/lib/python2.7/site-packages/sqlalchemy/pool.py", line 788, in _do_get
    con = self._create_connection()
  File "/usr/local/lib/python2.7/site-packages/sqlalchemy/pool.py", line 225, in _create_connection
    return _ConnectionRecord(self)
  File "/usr/local/lib/python2.7/site-packages/sqlalchemy/pool.py", line 318, in __init__
    self.connection = self.__connect()
  File "/usr/local/lib/python2.7/site-packages/sqlalchemy/pool.py", line 379, in __connect
    connection = self.__pool._creator()
  File "/usr/local/lib/python2.7/site-packages/sqlalchemy/engine/strategies.py", line 80, in connect
    return dialect.connect(*cargs, **cparams)
  File "/usr/local/lib/python2.7/site-packages/sqlalchemy/engine/default.py", line 283, in connect
    return self.dbapi.connect(*cargs, **cparams)
  File "/usr/local/lib/python2.7/site-packages/psycopg2/__init__.py", line 130, in connect
    conn = _connect(dsn, connection_factory=connection_factory, **kwasync)
OperationalError: (OperationalError) could not connect to server: Network is down
	Is the server running on host "ec2-23-21-129-50.compute-1.amazonaws.com" (23.21.129.50) and accepting
	TCP/IP connections on port 5432?
 None None
Traceback (most recent call last):
  File "/usr/local/lib/python2.7/site-packages/gunicorn/arbiter.py", line 515, in spawn_worker
    worker.init_process()
  File "/usr/local/lib/python2.7/site-packages/gunicorn/workers/base.py", line 122, in init_process
    self.load_wsgi()
  File "/usr/local/lib/python2.7/site-packages/gunicorn/workers/base.py", line 130, in load_wsgi
    self.wsgi = self.app.wsgi()
  File "/usr/local/lib/python2.7/site-packages/gunicorn/app/base.py", line 67, in wsgi
    self.callable = self.load()
  File "/usr/local/lib/python2.7/site-packages/psiturk/experiment_server.py", line 47, in load
    return util.import_app("psiturk.experiment:app")
  File "/usr/local/lib/python2.7/site-packages/gunicorn/util.py", line 357, in import_app
    __import__(module)
  File "/usr/local/lib/python2.7/site-packages/psiturk/experiment.py", line 89, in <module>
    init_db()
  File "/usr/local/lib/python2.7/site-packages/psiturk/db.py", line 37, in init_db
    Base.metadata.create_all(bind=engine)
  File "/usr/local/lib/python2.7/site-packages/sqlalchemy/schema.py", line 2848, in create_all
    tables=tables)
  File "/usr/local/lib/python2.7/site-packages/sqlalchemy/engine/base.py", line 1478, in _run_visitor
    with self._optional_conn_ctx_manager(connection) as conn:
  File "/usr/local/Cellar/python@2/2.7.15/Frameworks/Python.framework/Versions/2.7/lib/python2.7/contextlib.py", line 17, in __enter__
    return self.gen.next()
  File "/usr/local/lib/python2.7/site-packages/sqlalchemy/engine/base.py", line 1471, in _optional_conn_ctx_manager
    with self.contextual_connect() as conn:
  File "/usr/local/lib/python2.7/site-packages/sqlalchemy/engine/base.py", line 1661, in contextual_connect
    self.pool.connect(),
  File "/usr/local/lib/python2.7/site-packages/sqlalchemy/pool.py", line 272, in connect
    return _ConnectionFairy(self).checkout()
  File "/usr/local/lib/python2.7/site-packages/sqlalchemy/pool.py", line 431, in __init__
    rec = self._connection_record = pool._do_get()
  File "/usr/local/lib/python2.7/site-packages/sqlalchemy/pool.py", line 788, in _do_get
    con = self._create_connection()
  File "/usr/local/lib/python2.7/site-packages/sqlalchemy/pool.py", line 225, in _create_connection
    return _ConnectionRecord(self)
  File "/usr/local/lib/python2.7/site-packages/sqlalchemy/pool.py", line 318, in __init__
    self.connection = self.__connect()
  File "/usr/local/lib/python2.7/site-packages/sqlalchemy/pool.py", line 379, in __connect
    connection = self.__pool._creator()
  File "/usr/local/lib/python2.7/site-packages/sqlalchemy/engine/strategies.py", line 80, in connect
    return dialect.connect(*cargs, **cparams)
  File "/usr/local/lib/python2.7/site-packages/sqlalchemy/engine/default.py", line 283, in connect
    return self.dbapi.connect(*cargs, **cparams)
  File "/usr/local/lib/python2.7/site-packages/psycopg2/__init__.py", line 130, in connect
    conn = _connect(dsn, connection_factory=connection_factory, **kwasync)
OperationalError: (OperationalError) could not connect to server: Network is down
	Is the server running on host "ec2-23-21-129-50.compute-1.amazonaws.com" (23.21.129.50) and accepting
	TCP/IP connections on port 5432?
 None None
[2018-06-06 18:59:05 -0700] [84949] [ERROR] Exception in worker process:
Traceback (most recent call last):
  File "/usr/local/lib/python2.7/site-packages/gunicorn/arbiter.py", line 515, in spawn_worker
    worker.init_process()
  File "/usr/local/lib/python2.7/site-packages/gunicorn/workers/base.py", line 122, in init_process
    self.load_wsgi()
  File "/usr/local/lib/python2.7/site-packages/gunicorn/workers/base.py", line 130, in load_wsgi
    self.wsgi = self.app.wsgi()
  File "/usr/local/lib/python2.7/site-packages/gunicorn/app/base.py", line 67, in wsgi
    self.callable = self.load()
  File "/usr/local/lib/python2.7/site-packages/psiturk/experiment_server.py", line 47, in load
    return util.import_app("psiturk.experiment:app")
  File "/usr/local/lib/python2.7/site-packages/gunicorn/util.py", line 357, in import_app
    __import__(module)
  File "/usr/local/lib/python2.7/site-packages/psiturk/experiment.py", line 89, in <module>
    init_db()
  File "/usr/local/lib/python2.7/site-packages/psiturk/db.py", line 37, in init_db
    Base.metadata.create_all(bind=engine)
  File "/usr/local/lib/python2.7/site-packages/sqlalchemy/schema.py", line 2848, in create_all
    tables=tables)
  File "/usr/local/lib/python2.7/site-packages/sqlalchemy/engine/base.py", line 1478, in _run_visitor
    with self._optional_conn_ctx_manager(connection) as conn:
  File "/usr/local/Cellar/python@2/2.7.15/Frameworks/Python.framework/Versions/2.7/lib/python2.7/contextlib.py", line 17, in __enter__
    return self.gen.next()
  File "/usr/local/lib/python2.7/site-packages/sqlalchemy/engine/base.py", line 1471, in _optional_conn_ctx_manager
    with self.contextual_connect() as conn:
  File "/usr/local/lib/python2.7/site-packages/sqlalchemy/engine/base.py", line 1661, in contextual_connect
    self.pool.connect(),
  File "/usr/local/lib/python2.7/site-packages/sqlalchemy/pool.py", line 272, in connect
    return _ConnectionFairy(self).checkout()
  File "/usr/local/lib/python2.7/site-packages/sqlalchemy/pool.py", line 431, in __init__
    rec = self._connection_record = pool._do_get()
  File "/usr/local/lib/python2.7/site-packages/sqlalchemy/pool.py", line 788, in _do_get
    con = self._create_connection()
  File "/usr/local/lib/python2.7/site-packages/sqlalchemy/pool.py", line 225, in _create_connection
    return _ConnectionRecord(self)
  File "/usr/local/lib/python2.7/site-packages/sqlalchemy/pool.py", line 318, in __init__
    self.connection = self.__connect()
  File "/usr/local/lib/python2.7/site-packages/sqlalchemy/pool.py", line 379, in __connect
    connection = self.__pool._creator()
  File "/usr/local/lib/python2.7/site-packages/sqlalchemy/engine/strategies.py", line 80, in connect
    return dialect.connect(*cargs, **cparams)
  File "/usr/local/lib/python2.7/site-packages/sqlalchemy/engine/default.py", line 283, in connect
    return self.dbapi.connect(*cargs, **cparams)
  File "/usr/local/lib/python2.7/site-packages/psycopg2/__init__.py", line 130, in connect
    conn = _connect(dsn, connection_factory=connection_factory, **kwasync)
OperationalError: (OperationalError) could not connect to server: Network is down
	Is the server running on host "ec2-23-21-129-50.compute-1.amazonaws.com" (23.21.129.50) and accepting
	TCP/IP connections on port 5432?
 None None
Traceback (most recent call last):
  File "/usr/local/lib/python2.7/site-packages/gunicorn/arbiter.py", line 515, in spawn_worker
    worker.init_process()
  File "/usr/local/lib/python2.7/site-packages/gunicorn/workers/base.py", line 122, in init_process
    self.load_wsgi()
  File "/usr/local/lib/python2.7/site-packages/gunicorn/workers/base.py", line 130, in load_wsgi
    self.wsgi = self.app.wsgi()
  File "/usr/local/lib/python2.7/site-packages/gunicorn/app/base.py", line 67, in wsgi
    self.callable = self.load()
  File "/usr/local/lib/python2.7/site-packages/psiturk/experiment_server.py", line 47, in load
    return util.import_app("psiturk.experiment:app")
  File "/usr/local/lib/python2.7/site-packages/gunicorn/util.py", line 357, in import_app
    __import__(module)
  File "/usr/local/lib/python2.7/site-packages/psiturk/experiment.py", line 89, in <module>
    init_db()
  File "/usr/local/lib/python2.7/site-packages/psiturk/db.py", line 37, in init_db
    Base.metadata.create_all(bind=engine)
  File "/usr/local/lib/python2.7/site-packages/sqlalchemy/schema.py", line 2848, in create_all
    tables=tables)
  File "/usr/local/lib/python2.7/site-packages/sqlalchemy/engine/base.py", line 1478, in _run_visitor
    with self._optional_conn_ctx_manager(connection) as conn:
  File "/usr/local/Cellar/python@2/2.7.15/Frameworks/Python.framework/Versions/2.7/lib/python2.7/contextlib.py", line 17, in __enter__
    return self.gen.next()
  File "/usr/local/lib/python2.7/site-packages/sqlalchemy/engine/base.py", line 1471, in _optional_conn_ctx_manager
    with self.contextual_connect() as conn:
  File "/usr/local/lib/python2.7/site-packages/sqlalchemy/engine/base.py", line 1661, in contextual_connect
    self.pool.connect(),
  File "/usr/local/lib/python2.7/site-packages/sqlalchemy/pool.py", line 272, in connect
    return _ConnectionFairy(self).checkout()
  File "/usr/local/lib/python2.7/site-packages/sqlalchemy/pool.py", line 431, in __init__
    rec = self._connection_record = pool._do_get()
  File "/usr/local/lib/python2.7/site-packages/sqlalchemy/pool.py", line 788, in _do_get
    con = self._create_connection()
  File "/usr/local/lib/python2.7/site-packages/sqlalchemy/pool.py", line 225, in _create_connection
    return _ConnectionRecord(self)
  File "/usr/local/lib/python2.7/site-packages/sqlalchemy/pool.py", line 318, in __init__
    self.connection = self.__connect()
  File "/usr/local/lib/python2.7/site-packages/sqlalchemy/pool.py", line 379, in __connect
    connection = self.__pool._creator()
  File "/usr/local/lib/python2.7/site-packages/sqlalchemy/engine/strategies.py", line 80, in connect
    return dialect.connect(*cargs, **cparams)
  File "/usr/local/lib/python2.7/site-packages/sqlalchemy/engine/default.py", line 283, in connect
    return self.dbapi.connect(*cargs, **cparams)
  File "/usr/local/lib/python2.7/site-packages/psycopg2/__init__.py", line 130, in connect
    conn = _connect(dsn, connection_factory=connection_factory, **kwasync)
OperationalError: (OperationalError) could not connect to server: Network is down
	Is the server running on host "ec2-23-21-129-50.compute-1.amazonaws.com" (23.21.129.50) and accepting
	TCP/IP connections on port 5432?
 None None
[2018-06-06 18:59:05 -0700] [84948] [ERROR] Exception in worker process:
Traceback (most recent call last):
  File "/usr/local/lib/python2.7/site-packages/gunicorn/arbiter.py", line 515, in spawn_worker
    worker.init_process()
  File "/usr/local/lib/python2.7/site-packages/gunicorn/workers/base.py", line 122, in init_process
    self.load_wsgi()
  File "/usr/local/lib/python2.7/site-packages/gunicorn/workers/base.py", line 130, in load_wsgi
    self.wsgi = self.app.wsgi()
  File "/usr/local/lib/python2.7/site-packages/gunicorn/app/base.py", line 67, in wsgi
    self.callable = self.load()
  File "/usr/local/lib/python2.7/site-packages/psiturk/experiment_server.py", line 47, in load
    return util.import_app("psiturk.experiment:app")
  File "/usr/local/lib/python2.7/site-packages/gunicorn/util.py", line 357, in import_app
    __import__(module)
  File "/usr/local/lib/python2.7/site-packages/psiturk/experiment.py", line 89, in <module>
    init_db()
  File "/usr/local/lib/python2.7/site-packages/psiturk/db.py", line 37, in init_db
    Base.metadata.create_all(bind=engine)
  File "/usr/local/lib/python2.7/site-packages/sqlalchemy/schema.py", line 2848, in create_all
    tables=tables)
  File "/usr/local/lib/python2.7/site-packages/sqlalchemy/engine/base.py", line 1478, in _run_visitor
    with self._optional_conn_ctx_manager(connection) as conn:
  File "/usr/local/Cellar/python@2/2.7.15/Frameworks/Python.framework/Versions/2.7/lib/python2.7/contextlib.py", line 17, in __enter__
    return self.gen.next()
  File "/usr/local/lib/python2.7/site-packages/sqlalchemy/engine/base.py", line 1471, in _optional_conn_ctx_manager
    with self.contextual_connect() as conn:
  File "/usr/local/lib/python2.7/site-packages/sqlalchemy/engine/base.py", line 1661, in contextual_connect
    self.pool.connect(),
  File "/usr/local/lib/python2.7/site-packages/sqlalchemy/pool.py", line 272, in connect
    return _ConnectionFairy(self).checkout()
  File "/usr/local/lib/python2.7/site-packages/sqlalchemy/pool.py", line 431, in __init__
    rec = self._connection_record = pool._do_get()
  File "/usr/local/lib/python2.7/site-packages/sqlalchemy/pool.py", line 788, in _do_get
    con = self._create_connection()
  File "/usr/local/lib/python2.7/site-packages/sqlalchemy/pool.py", line 225, in _create_connection
    return _ConnectionRecord(self)
  File "/usr/local/lib/python2.7/site-packages/sqlalchemy/pool.py", line 318, in __init__
    self.connection = self.__connect()
  File "/usr/local/lib/python2.7/site-packages/sqlalchemy/pool.py", line 379, in __connect
    connection = self.__pool._creator()
  File "/usr/local/lib/python2.7/site-packages/sqlalchemy/engine/strategies.py", line 80, in connect
    return dialect.connect(*cargs, **cparams)
  File "/usr/local/lib/python2.7/site-packages/sqlalchemy/engine/default.py", line 283, in connect
    return self.dbapi.connect(*cargs, **cparams)
  File "/usr/local/lib/python2.7/site-packages/psycopg2/__init__.py", line 130, in connect
    conn = _connect(dsn, connection_factory=connection_factory, **kwasync)
OperationalError: (OperationalError) could not connect to server: Network is down
	Is the server running on host "ec2-23-21-129-50.compute-1.amazonaws.com" (23.21.129.50) and accepting
	TCP/IP connections on port 5432?
 None None
Traceback (most recent call last):
  File "/usr/local/lib/python2.7/site-packages/gunicorn/arbiter.py", line 515, in spawn_worker
    worker.init_process()
  File "/usr/local/lib/python2.7/site-packages/gunicorn/workers/base.py", line 122, in init_process
    self.load_wsgi()
  File "/usr/local/lib/python2.7/site-packages/gunicorn/workers/base.py", line 130, in load_wsgi
    self.wsgi = self.app.wsgi()
  File "/usr/local/lib/python2.7/site-packages/gunicorn/app/base.py", line 67, in wsgi
    self.callable = self.load()
  File "/usr/local/lib/python2.7/site-packages/psiturk/experiment_server.py", line 47, in load
    return util.import_app("psiturk.experiment:app")
  File "/usr/local/lib/python2.7/site-packages/gunicorn/util.py", line 357, in import_app
    __import__(module)
  File "/usr/local/lib/python2.7/site-packages/psiturk/experiment.py", line 89, in <module>
    init_db()
  File "/usr/local/lib/python2.7/site-packages/psiturk/db.py", line 37, in init_db
    Base.metadata.create_all(bind=engine)
  File "/usr/local/lib/python2.7/site-packages/sqlalchemy/schema.py", line 2848, in create_all
    tables=tables)
  File "/usr/local/lib/python2.7/site-packages/sqlalchemy/engine/base.py", line 1478, in _run_visitor
    with self._optional_conn_ctx_manager(connection) as conn:
  File "/usr/local/Cellar/python@2/2.7.15/Frameworks/Python.framework/Versions/2.7/lib/python2.7/contextlib.py", line 17, in __enter__
    return self.gen.next()
  File "/usr/local/lib/python2.7/site-packages/sqlalchemy/engine/base.py", line 1471, in _optional_conn_ctx_manager
    with self.contextual_connect() as conn:
  File "/usr/local/lib/python2.7/site-packages/sqlalchemy/engine/base.py", line 1661, in contextual_connect
    self.pool.connect(),
  File "/usr/local/lib/python2.7/site-packages/sqlalchemy/pool.py", line 272, in connect
    return _ConnectionFairy(self).checkout()
  File "/usr/local/lib/python2.7/site-packages/sqlalchemy/pool.py", line 431, in __init__
    rec = self._connection_record = pool._do_get()
  File "/usr/local/lib/python2.7/site-packages/sqlalchemy/pool.py", line 788, in _do_get
    con = self._create_connection()
  File "/usr/local/lib/python2.7/site-packages/sqlalchemy/pool.py", line 225, in _create_connection
    return _ConnectionRecord(self)
  File "/usr/local/lib/python2.7/site-packages/sqlalchemy/pool.py", line 318, in __init__
    self.connection = self.__connect()
  File "/usr/local/lib/python2.7/site-packages/sqlalchemy/pool.py", line 379, in __connect
    connection = self.__pool._creator()
  File "/usr/local/lib/python2.7/site-packages/sqlalchemy/engine/strategies.py", line 80, in connect
    return dialect.connect(*cargs, **cparams)
  File "/usr/local/lib/python2.7/site-packages/sqlalchemy/engine/default.py", line 283, in connect
    return self.dbapi.connect(*cargs, **cparams)
  File "/usr/local/lib/python2.7/site-packages/psycopg2/__init__.py", line 130, in connect
    conn = _connect(dsn, connection_factory=connection_factory, **kwasync)
OperationalError: (OperationalError) could not connect to server: Network is down
	Is the server running on host "ec2-23-21-129-50.compute-1.amazonaws.com" (23.21.129.50) and accepting
	TCP/IP connections on port 5432?
 None None
[2018-06-06 18:59:05 -0700] [84950] [ERROR] Exception in worker process:
Traceback (most recent call last):
  File "/usr/local/lib/python2.7/site-packages/gunicorn/arbiter.py", line 515, in spawn_worker
    worker.init_process()
  File "/usr/local/lib/python2.7/site-packages/gunicorn/workers/base.py", line 122, in init_process
    self.load_wsgi()
  File "/usr/local/lib/python2.7/site-packages/gunicorn/workers/base.py", line 130, in load_wsgi
    self.wsgi = self.app.wsgi()
  File "/usr/local/lib/python2.7/site-packages/gunicorn/app/base.py", line 67, in wsgi
    self.callable = self.load()
  File "/usr/local/lib/python2.7/site-packages/psiturk/experiment_server.py", line 47, in load
    return util.import_app("psiturk.experiment:app")
  File "/usr/local/lib/python2.7/site-packages/gunicorn/util.py", line 357, in import_app
    __import__(module)
  File "/usr/local/lib/python2.7/site-packages/psiturk/experiment.py", line 89, in <module>
    init_db()
  File "/usr/local/lib/python2.7/site-packages/psiturk/db.py", line 37, in init_db
    Base.metadata.create_all(bind=engine)
  File "/usr/local/lib/python2.7/site-packages/sqlalchemy/schema.py", line 2848, in create_all
    tables=tables)
  File "/usr/local/lib/python2.7/site-packages/sqlalchemy/engine/base.py", line 1478, in _run_visitor
    with self._optional_conn_ctx_manager(connection) as conn:
  File "/usr/local/Cellar/python@2/2.7.15/Frameworks/Python.framework/Versions/2.7/lib/python2.7/contextlib.py", line 17, in __enter__
    return self.gen.next()
  File "/usr/local/lib/python2.7/site-packages/sqlalchemy/engine/base.py", line 1471, in _optional_conn_ctx_manager
    with self.contextual_connect() as conn:
  File "/usr/local/lib/python2.7/site-packages/sqlalchemy/engine/base.py", line 1661, in contextual_connect
    self.pool.connect(),
  File "/usr/local/lib/python2.7/site-packages/sqlalchemy/pool.py", line 272, in connect
    return _ConnectionFairy(self).checkout()
  File "/usr/local/lib/python2.7/site-packages/sqlalchemy/pool.py", line 431, in __init__
    rec = self._connection_record = pool._do_get()
  File "/usr/local/lib/python2.7/site-packages/sqlalchemy/pool.py", line 788, in _do_get
    con = self._create_connection()
  File "/usr/local/lib/python2.7/site-packages/sqlalchemy/pool.py", line 225, in _create_connection
    return _ConnectionRecord(self)
  File "/usr/local/lib/python2.7/site-packages/sqlalchemy/pool.py", line 318, in __init__
    self.connection = self.__connect()
  File "/usr/local/lib/python2.7/site-packages/sqlalchemy/pool.py", line 379, in __connect
    connection = self.__pool._creator()
  File "/usr/local/lib/python2.7/site-packages/sqlalchemy/engine/strategies.py", line 80, in connect
    return dialect.connect(*cargs, **cparams)
  File "/usr/local/lib/python2.7/site-packages/sqlalchemy/engine/default.py", line 283, in connect
    return self.dbapi.connect(*cargs, **cparams)
  File "/usr/local/lib/python2.7/site-packages/psycopg2/__init__.py", line 130, in connect
    conn = _connect(dsn, connection_factory=connection_factory, **kwasync)
OperationalError: (OperationalError) could not connect to server: Network is down
	Is the server running on host "ec2-23-21-129-50.compute-1.amazonaws.com" (23.21.129.50) and accepting
	TCP/IP connections on port 5432?
 None None
Traceback (most recent call last):
  File "/usr/local/lib/python2.7/site-packages/gunicorn/arbiter.py", line 515, in spawn_worker
    worker.init_process()
  File "/usr/local/lib/python2.7/site-packages/gunicorn/workers/base.py", line 122, in init_process
    self.load_wsgi()
  File "/usr/local/lib/python2.7/site-packages/gunicorn/workers/base.py", line 130, in load_wsgi
    self.wsgi = self.app.wsgi()
  File "/usr/local/lib/python2.7/site-packages/gunicorn/app/base.py", line 67, in wsgi
    self.callable = self.load()
  File "/usr/local/lib/python2.7/site-packages/psiturk/experiment_server.py", line 47, in load
    return util.import_app("psiturk.experiment:app")
  File "/usr/local/lib/python2.7/site-packages/gunicorn/util.py", line 357, in import_app
    __import__(module)
  File "/usr/local/lib/python2.7/site-packages/psiturk/experiment.py", line 89, in <module>
    init_db()
  File "/usr/local/lib/python2.7/site-packages/psiturk/db.py", line 37, in init_db
    Base.metadata.create_all(bind=engine)
  File "/usr/local/lib/python2.7/site-packages/sqlalchemy/schema.py", line 2848, in create_all
    tables=tables)
  File "/usr/local/lib/python2.7/site-packages/sqlalchemy/engine/base.py", line 1478, in _run_visitor
    with self._optional_conn_ctx_manager(connection) as conn:
  File "/usr/local/Cellar/python@2/2.7.15/Frameworks/Python.framework/Versions/2.7/lib/python2.7/contextlib.py", line 17, in __enter__
    return self.gen.next()
  File "/usr/local/lib/python2.7/site-packages/sqlalchemy/engine/base.py", line 1471, in _optional_conn_ctx_manager
    with self.contextual_connect() as conn:
  File "/usr/local/lib/python2.7/site-packages/sqlalchemy/engine/base.py", line 1661, in contextual_connect
    self.pool.connect(),
  File "/usr/local/lib/python2.7/site-packages/sqlalchemy/pool.py", line 272, in connect
    return _ConnectionFairy(self).checkout()
  File "/usr/local/lib/python2.7/site-packages/sqlalchemy/pool.py", line 431, in __init__
    rec = self._connection_record = pool._do_get()
  File "/usr/local/lib/python2.7/site-packages/sqlalchemy/pool.py", line 788, in _do_get
    con = self._create_connection()
  File "/usr/local/lib/python2.7/site-packages/sqlalchemy/pool.py", line 225, in _create_connection
    return _ConnectionRecord(self)
  File "/usr/local/lib/python2.7/site-packages/sqlalchemy/pool.py", line 318, in __init__
    self.connection = self.__connect()
  File "/usr/local/lib/python2.7/site-packages/sqlalchemy/pool.py", line 379, in __connect
    connection = self.__pool._creator()
  File "/usr/local/lib/python2.7/site-packages/sqlalchemy/engine/strategies.py", line 80, in connect
    return dialect.connect(*cargs, **cparams)
  File "/usr/local/lib/python2.7/site-packages/sqlalchemy/engine/default.py", line 283, in connect
    return self.dbapi.connect(*cargs, **cparams)
  File "/usr/local/lib/python2.7/site-packages/psycopg2/__init__.py", line 130, in connect
    conn = _connect(dsn, connection_factory=connection_factory, **kwasync)
OperationalError: (OperationalError) could not connect to server: Network is down
	Is the server running on host "ec2-23-21-129-50.compute-1.amazonaws.com" (23.21.129.50) and accepting
	TCP/IP connections on port 5432?
 None None
